[2023-04-25T08:35:13.787+0000] {taskinstance.py:1083} INFO - Dependencies all met for <TaskInstance: database_processing.insert_into_table manual__2023-04-25T08:35:11.712214+00:00 [queued]>
[2023-04-25T08:35:13.800+0000] {taskinstance.py:1083} INFO - Dependencies all met for <TaskInstance: database_processing.insert_into_table manual__2023-04-25T08:35:11.712214+00:00 [queued]>
[2023-04-25T08:35:13.801+0000] {taskinstance.py:1279} INFO - 
--------------------------------------------------------------------------------
[2023-04-25T08:35:13.802+0000] {taskinstance.py:1280} INFO - Starting attempt 1 of 1
[2023-04-25T08:35:13.802+0000] {taskinstance.py:1281} INFO - 
--------------------------------------------------------------------------------
[2023-04-25T08:35:13.816+0000] {taskinstance.py:1300} INFO - Executing <Task(PostgresOperator): insert_into_table> on 2023-04-25 08:35:11.712214+00:00
[2023-04-25T08:35:13.827+0000] {standard_task_runner.py:55} INFO - Started process 9386 to run task
[2023-04-25T08:35:13.834+0000] {standard_task_runner.py:82} INFO - Running: ['***', 'tasks', 'run', 'database_processing', 'insert_into_table', 'manual__2023-04-25T08:35:11.712214+00:00', '--job-id', '16', '--raw', '--subdir', 'DAGS_FOLDER/database_processing.py', '--cfg-path', '/tmp/tmp9ru07ru6']
[2023-04-25T08:35:13.836+0000] {standard_task_runner.py:83} INFO - Job 16: Subtask insert_into_table
[2023-04-25T08:35:13.923+0000] {task_command.py:388} INFO - Running <TaskInstance: database_processing.insert_into_table manual__2023-04-25T08:35:11.712214+00:00 [running]> on host 2f9666fcabde
[2023-04-25T08:35:13.975+0000] {taskinstance.py:1509} INFO - Exporting the following env vars:
AIRFLOW_CTX_DAG_OWNER=***
AIRFLOW_CTX_DAG_ID=database_processing
AIRFLOW_CTX_TASK_ID=insert_into_table
AIRFLOW_CTX_EXECUTION_DATE=2023-04-25T08:35:11.712214+00:00
AIRFLOW_CTX_TRY_NUMBER=1
AIRFLOW_CTX_DAG_RUN_ID=manual__2023-04-25T08:35:11.712214+00:00
[2023-04-25T08:35:13.976+0000] {sql.py:254} INFO - Executing: 
            INSERT INTO USERS VALUES
            (2,'shubham','rshuh@gmail.com','+917938535736','hyderabad','amazon'),
            (3,'pankaj','pankajksh@gmail.com','+917838895736','bihar','apple'),
            (4,'raj','rajkumar@gmail.com','+916783456890','ranchi','aidash');
        
[2023-04-25T08:35:13.984+0000] {base.py:73} INFO - Using connection ID 'postgres' for task execution.
[2023-04-25T08:35:14.089+0000] {base.py:73} INFO - Using connection ID 'postgres' for task execution.
[2023-04-25T08:35:14.095+0000] {sql.py:375} INFO - Running statement: 
            INSERT INTO USERS VALUES
            (2,'shubham','rshuh@gmail.com','+917938535736','hyderabad','amazon'),
            (3,'pankaj','pankajksh@gmail.com','+917838895736','bihar','apple'),
            (4,'raj','rajkumar@gmail.com','+916783456890','ranchi','aidash');
        , parameters: None
[2023-04-25T08:35:14.098+0000] {taskinstance.py:1768} ERROR - Task failed with exception
Traceback (most recent call last):
  File "/home/airflow/.local/lib/python3.7/site-packages/airflow/providers/common/sql/operators/sql.py", line 266, in execute
    **extra_kwargs,
  File "/home/airflow/.local/lib/python3.7/site-packages/airflow/providers/common/sql/hooks/sql.py", line 349, in run
    self._run_command(cur, sql_statement, parameters)
  File "/home/airflow/.local/lib/python3.7/site-packages/airflow/providers/common/sql/hooks/sql.py", line 380, in _run_command
    cur.execute(sql_statement)
psycopg2.errors.UniqueViolation: duplicate key value violates unique constraint "users_pkey"
DETAIL:  Key (id)=(2) already exists.

[2023-04-25T08:35:14.123+0000] {taskinstance.py:1323} INFO - Marking task as FAILED. dag_id=database_processing, task_id=insert_into_table, execution_date=20230425T083511, start_date=20230425T083513, end_date=20230425T083514
[2023-04-25T08:35:14.131+0000] {standard_task_runner.py:105} ERROR - Failed to execute job 16 for task insert_into_table (duplicate key value violates unique constraint "users_pkey"
DETAIL:  Key (id)=(2) already exists.
; 9386)
[2023-04-25T08:35:14.174+0000] {local_task_job.py:208} INFO - Task exited with return code 1
[2023-04-25T08:35:14.192+0000] {taskinstance.py:2578} INFO - 0 downstream tasks scheduled from follow-on schedule check
