[2023-04-25T07:59:41.669+0000] {taskinstance.py:1083} INFO - Dependencies all met for <TaskInstance: database_processing.insert_into_table manual__2023-04-25T07:59:39.708601+00:00 [queued]>
[2023-04-25T07:59:41.676+0000] {taskinstance.py:1083} INFO - Dependencies all met for <TaskInstance: database_processing.insert_into_table manual__2023-04-25T07:59:39.708601+00:00 [queued]>
[2023-04-25T07:59:41.676+0000] {taskinstance.py:1279} INFO - 
--------------------------------------------------------------------------------
[2023-04-25T07:59:41.677+0000] {taskinstance.py:1280} INFO - Starting attempt 1 of 1
[2023-04-25T07:59:41.677+0000] {taskinstance.py:1281} INFO - 
--------------------------------------------------------------------------------
[2023-04-25T07:59:41.685+0000] {taskinstance.py:1300} INFO - Executing <Task(PostgresOperator): insert_into_table> on 2023-04-25 07:59:39.708601+00:00
[2023-04-25T07:59:41.690+0000] {standard_task_runner.py:55} INFO - Started process 8697 to run task
[2023-04-25T07:59:41.694+0000] {standard_task_runner.py:82} INFO - Running: ['***', 'tasks', 'run', 'database_processing', 'insert_into_table', 'manual__2023-04-25T07:59:39.708601+00:00', '--job-id', '12', '--raw', '--subdir', 'DAGS_FOLDER/database_processing.py', '--cfg-path', '/tmp/tmpaizc3i9i']
[2023-04-25T07:59:41.695+0000] {standard_task_runner.py:83} INFO - Job 12: Subtask insert_into_table
[2023-04-25T07:59:41.747+0000] {task_command.py:388} INFO - Running <TaskInstance: database_processing.insert_into_table manual__2023-04-25T07:59:39.708601+00:00 [running]> on host 2f9666fcabde
[2023-04-25T07:59:41.806+0000] {taskinstance.py:1509} INFO - Exporting the following env vars:
AIRFLOW_CTX_DAG_OWNER=***
AIRFLOW_CTX_DAG_ID=database_processing
AIRFLOW_CTX_TASK_ID=insert_into_table
AIRFLOW_CTX_EXECUTION_DATE=2023-04-25T07:59:39.708601+00:00
AIRFLOW_CTX_TRY_NUMBER=1
AIRFLOW_CTX_DAG_RUN_ID=manual__2023-04-25T07:59:39.708601+00:00
[2023-04-25T07:59:41.807+0000] {sql.py:254} INFO - Executing: 
            INSERT INTO USERS VALUES
            (1,'rahul','rahulksh@gmail.com','+917838535736','bihar','sigmoid'),
            (2,'shubham','rshuh@gmail.com','+917938535736','hyderabad','amazon'),
            (3,'pankaj','pankajksh@gmail.com','+917838895736','bihar','apple'),
            (4,'raj','rajkumar@gmail.com','+916783456890','ranchi','aidash');
        
[2023-04-25T07:59:41.816+0000] {base.py:73} INFO - Using connection ID 'postgres' for task execution.
[2023-04-25T07:59:41.925+0000] {base.py:73} INFO - Using connection ID 'postgres' for task execution.
[2023-04-25T07:59:41.930+0000] {sql.py:375} INFO - Running statement: 
            INSERT INTO USERS VALUES
            (1,'rahul','rahulksh@gmail.com','+917838535736','bihar','sigmoid'),
            (2,'shubham','rshuh@gmail.com','+917938535736','hyderabad','amazon'),
            (3,'pankaj','pankajksh@gmail.com','+917838895736','bihar','apple'),
            (4,'raj','rajkumar@gmail.com','+916783456890','ranchi','aidash');
        , parameters: None
[2023-04-25T07:59:41.932+0000] {taskinstance.py:1768} ERROR - Task failed with exception
Traceback (most recent call last):
  File "/home/airflow/.local/lib/python3.7/site-packages/airflow/providers/common/sql/operators/sql.py", line 266, in execute
    **extra_kwargs,
  File "/home/airflow/.local/lib/python3.7/site-packages/airflow/providers/common/sql/hooks/sql.py", line 349, in run
    self._run_command(cur, sql_statement, parameters)
  File "/home/airflow/.local/lib/python3.7/site-packages/airflow/providers/common/sql/hooks/sql.py", line 380, in _run_command
    cur.execute(sql_statement)
psycopg2.errors.UniqueViolation: duplicate key value violates unique constraint "users_pkey"
DETAIL:  Key (id)=(1) already exists.

[2023-04-25T07:59:41.941+0000] {taskinstance.py:1323} INFO - Marking task as FAILED. dag_id=database_processing, task_id=insert_into_table, execution_date=20230425T075939, start_date=20230425T075941, end_date=20230425T075941
[2023-04-25T07:59:41.949+0000] {standard_task_runner.py:105} ERROR - Failed to execute job 12 for task insert_into_table (duplicate key value violates unique constraint "users_pkey"
DETAIL:  Key (id)=(1) already exists.
; 8697)
[2023-04-25T07:59:41.987+0000] {local_task_job.py:208} INFO - Task exited with return code 1
[2023-04-25T07:59:42.004+0000] {taskinstance.py:2578} INFO - 0 downstream tasks scheduled from follow-on schedule check
